Workbook

Sheet Jira Import
A1: Issue ID | B1: Parent ID | C1: Issue Type | D1: Summary | E1: Description | F1: Epic Name | G1: Epic Link | H1: Priority | I1: Story Points | J1: Original Estimate (h) | K1: Component | L1: Milestone | M1: Labels | N1: Status | O1: Status note | P1: Updated
A2: EPIC-A | C2: Epic | D2: A — Foundation & tenancy | E2: Auth, workspaces, spaces, folders and the application-layer scoping that isolates every tenant. | F2: Foundation & tenancy | I2: =SUMIFS(I$2:I$273,G$2:G$273,"EPIC-A",C$2:C$273,"Story") | J2: =SUMIFS(J$2:J$273,G$2:G$273,"EPIC-A",C$2:C$273,"Story") | M2: epic | N2: Done | O2: 20/20 sub-tasks done, 5/5 stories done | P2: 2026-09-22
A3: A1 | B3: EPIC-A | C3: Story | D3: As a new user, I can sign up and create a workspace so I have somewhere to put documents. | E3: Email plus magic-link auth. Creating a workspace makes the creator its admin. | G3: EPIC-A | H3: Highest | I3: 5 | J3: =SUM(J4:J7) | L3: M0 Foundation | M3: p0,m0 | N3: Done | O3: 4/4 sub-tasks done | P3: 2026-09-22
A4: A1-T1 | B4: A1 | C4: Sub-task | D4: Sanctum SPA session auth plus signed-URL magic links | H4: Highest | J4: 10 | K4: Backend | L4: M0 Foundation | M4: backend | N4: Done | O4: Sanctum + signed magic links; b58a0df | P4: 2026-09-22
A5: A1-T2 | B5: A1 | C5: Sub-task | D5: Build sign in / sign up screen (S1) | H5: Highest | J5: 8 | K5: Frontend | L5: M0 Foundation | M5: frontend | N5: Done | O5: S1 | P5: 2026-09-22
A6: A1-T3 | B6: A1 | C6: Sub-task | D6: Workspace creation flow with slug validation (S2) | H6: Highest | J6: 6 | K6: Full stack | L6: M0 Foundation | M6: full-stack | N6: Done | O6: S2 | P6: 2026-09-22
A7: A1-T4 | B7: A1 | C7: Sub-task | D7: Users table and workspace membership model | H7: Highest | J7: 4 | K7: Database | L7: M0 Foundation | M7: database | N7: Done | O7: users, workspace_members | P7: 2026-09-22
A8: A2 | B8: EPIC-A | C8: Story | D8: As an admin, I can invite teammates by email with a role so they can join the workspace. | E8: Invite by email with a role assigned at invite time. | G8: EPIC-A | H8: Highest | I8: 5 | J8: =SUM(J9:J11) | L8: M0 Foundation | M8: p0,m0 | N8: Done | O8: 3/3 sub-tasks done | P8: 2026-09-22
A9: A2-T1 | B9: A2 | C9: Sub-task | D9: Invite API with signed token and email delivery | H9: Highest | J9: 8 | K9: Backend | L9: M0 Foundation | M9: backend | N9: Done | O9: Invite API + WorkspaceInviteNotification | P9: 2026-09-22
A10: A2-T2 | B10: A2 | C10: Sub-task | D10: Invite and accept screens (S3) | H10: Highest | J10: 8 | K10: Frontend | L10: M0 Foundation | M10: frontend | N10: Done | O10: S3 + accept | P10: 2026-09-22
A11: A2-T3 | B11: A2 | C11: Sub-task | D11: Role assignment on invite acceptance | H11: Highest | J11: 4 | K11: Backend | L11: M0 Foundation | M11: backend | N11: Done | P11: 2026-09-22
A12: A3 | B12: EPIC-A | C12: Story | D12: As a developer, every tenant table is workspace-scoped by default so no query can cross a workspace boundary. | E12: Release blocker. MySQL has no row-level security, so the boundary is application-layer: a missed scope leaks rather than returning nothing. | G12: EPIC-A | H12: Highest | I12: 13 | J12: =SUM(J13:J19) | L12: M0 Foundation | M12: p0,m0 | N12: Done | O12: 7/7 sub-tasks done | P12: 2026-09-22
A13: A3-T1 | B13: A3 | C13: Sub-task | D13: Build TenantModel base class with mandatory workspace global scope | H13: Highest | J13: 10 | K13: Backend | L13: M0 Foundation | M13: backend | N13: Done | O13: TenantModel + TenantScope | P13: 2026-09-22
A14: A3-T2 | B14: A3 | C14: Sub-task | D14: Auto-set workspace_id on create from request context, never from payload | H14: Highest | J14: 5 | K14: Backend | L14: M0 Foundation | M14: backend | N14: Done | O14: workspace_id from CurrentWorkspace only | P14: 2026-09-22
A15: A3-T3 | B15: A3 | C15: Sub-task | D15: Laravel Policies for space-level access | H15: Highest | J15: 10 | K15: Backend | L15: M0 Foundation | M15: backend | N15: Done | O15: SpacePolicy/DocumentPolicy/RecordingPolicy | P15: 2026-09-22
A16: A3-T4 | B16: A3 | C16: Sub-task | D16: Schema conformance test: every tenant table scoped, indexed, non-fillable | H16: Highest | J16: 12 | K16: QA | L16: M0 Foundation | M16: qa | N16: Done | O16: SchemaConformanceTest | P16: 2026-09-22
A17: A3-T5 | B17: A3 | C17: Sub-task | D17: Static analysis rule blocking raw unscoped queries | H17: Highest | J17: 6 | K17: Infra | L17: M0 Foundation | M17: infra | N17: Done | O17: scripts/check-raw-queries.php | P17: 2026-09-22
A18: A3-T6 | B18: A3 | C18: Sub-task | D18: Cross-tenant and cross-table consistency test suite | H18: Highest | J18: 14 | K18: QA | L18: M0 Foundation | M18: qa | N18: Done | O18: CrossTenantIsolationTest | P18: 2026-09-22
A19: A3-T7 | B19: A3 | C19: Sub-task | D19: Wire all gates into CI as blocking | H19: Highest | J19: 3 | K19: Infra | L19: M0 Foundation | M19: infra | N19: Done | O19: ci.yml, all gates blocking | P19: 2026-09-22
A20: A4 | B20: EPIC-A | C20: Story | D20: As an admin, I can create spaces and folders so documentation matches how the company is organised. | E20: Workspace to space to folder, max depth 5. | G20: EPIC-A | H20: Highest | I20: 5 | J20: =SUM(J21:J23) | L20: M0 Foundation | M20: p0,m0 | N20: Done | O20: 3/3 sub-tasks done | P20: 2026-09-22
A21: A4-T1 | B21: A4 | C21: Sub-task | D21: Schema and migrations for spaces and folders | H21: Highest | J21: 5 | K21: Database | L21: M0 Foundation | M21: database | N21: Done | P21: 2026-09-22
A22: A4-T2 | B22: A4 | C22: Sub-task | D22: Folder CRUD API including move with depth check | H22: Highest | J22: 8 | K22: Backend | L22: M0 Foundation | M22: backend | N22: Done | O22: depth ≤ 5, delete strategy | P22: 2026-09-22
A23: A4-T3 | B23: A4 | C23: Sub-task | D23: Sidebar tree and space browser (S5, S6) | H23: Highest | J23: 10 | K23: Frontend | L23: M0 Foundation | M23: frontend | N23: Done | O23: S5, S6 | P23: 2026-09-22
A24: A5 | B24: EPIC-A | C24: Story | D24: As a user, I see only the spaces I'm a member of, everywhere in the product. | E24: No greyed-out items hinting at content behind a permission wall. | G24: EPIC-A | H24: Highest | I24: 3 | J24: =SUM(J25:J27) | L24: M0 Foundation | M24: p0,m0 | N24: Done | O24: 3/3 sub-tasks done | P24: 2026-09-22
A25: A5-T1 | B25: A5 | C25: Sub-task | D25: Scope sidebar and browser to accessible spaces | H25: Highest | J25: 5 | K25: Frontend | L25: M0 Foundation | M25: frontend | N25: Done | P25: 2026-09-22
A26: A5-T2 | B26: A5 | C26: Sub-task | D26: Return 403 not 404 so existence is never leaked | H26: Highest | J26: 5 | K26: Backend | L26: M0 Foundation | M26: backend | N26: Done | O26: ResolveWorkspace + bootstrap 404→403 | P26: 2026-09-22
A27: A5-T3 | B27: A5 | C27: Sub-task | D27: Permission visibility tests across surfaces | H27: Highest | J27: 4 | K27: QA | L27: M0 Foundation | M27: qa | N27: Done | P27: 2026-09-22
A28: EPIC-B | C28: Epic | D28: B — Editor & document model | E28: The block editor, the structured SOP model, templates and paste fidelity. | F28: Editor & document model | I28: =SUMIFS(I$2:I$273,G$2:G$273,"EPIC-B",C$2:C$273,"Story") | J28: =SUMIFS(J$2:J$273,G$2:G$273,"EPIC-B",C$2:C$273,"Story") | M28: epic | N28: Done | O28: 21/21 sub-tasks done, 7/7 stories done | P28: 2026-09-23
A29: B1 | B29: EPIC-B | C29: Story | D29: As an editor, I can write a document with headings, lists, tables, callouts and images. | E29: Content stored as structured JSON, never HTML, so diffing and chunking stay reliable. | G29: EPIC-B | H29: Highest | I29: 13 | J29: =SUM(J30:J34) | L29: M0 Foundation | M29: p0,m0 | N29: Done | O29: 5/5 sub-tasks done | P29: 2026-09-23
A30: B1-T1 | B30: B1 | C30: Sub-task | D30: Editor foundation and structured JSON document model | H30: Highest | J30: 20 | K30: Frontend | L30: M0 Foundation | M30: frontend | N30: Done | O30: structured JSON Content model | P30: 2026-09-22
A31: B1-T2 | B31: B1 | C31: Sub-task | D31: Core blocks: headings, lists, tables, callouts, code | H31: Highest | J31: 20 | K31: Frontend | L31: M0 Foundation | M31: frontend | N31: Done | O31: block-editor: all F2 types, slash menu; 44e896b | P31: 2026-09-22
A32: B1-T3 | B32: B1 | C32: Sub-task | D32: Image upload to object storage, referenced by ID | H32: Highest | J32: 10 | K32: Full stack | L32: M0 Foundation | M32: full-stack | N32: Done | O32: editor images/files: presigned PUT, complete, signed URL after policy check; paste/drop upload; commit pending | P32: 2026-09-23
A33: B1-T4 | B33: B1 | C33: Sub-task | D33: Reader render parity with editor | H33: Highest | J33: 8 | K33: Frontend | L33: M0 Foundation | M33: frontend | N33: Done | O33: reader renders every block type | P33: 2026-09-22
A34: B1-T5 | B34: B1 | C34: Sub-task | D34: Round-trip save/load fidelity tests | H34: Highest | J34: 6 | K34: QA | L34: M0 Foundation | M34: qa | N34: Done | O34: EditorCompletionTest: every block type round-trips exactly; unknown types rejected; commit pending | P34: 2026-09-23
A35: B2 | B35: EPIC-B | C35: Story | D35: As an editor, my work autosaves so I never lose a draft. | E35: Debounced at 2s with an explicit saved indicator, never a spinner. | G35: EPIC-B | H35: Highest | I35: 3 | J35: =SUM(J36:J38) | L35: M0 Foundation | M35: p0,m0 | N35: Done | O35: 3/3 sub-tasks done | P35: 2026-09-23
A36: B2-T1 | B36: B2 | C36: Sub-task | D36: Debounced autosave and saved-state indicator | H36: Highest | J36: 6 | K36: Frontend | L36: M0 Foundation | M36: frontend | N36: Done | O36: 2 s debounce, Saved hh:mm | P36: 2026-09-22
A37: B2-T2 | B37: B2 | C37: Sub-task | D37: Optimistic concurrency via expected_updated_at and 409 | H37: Highest | J37: 6 | K37: Backend | L37: M0 Foundation | M37: backend | N37: Done | O37: expected_updated_at → 409 | P37: 2026-09-22
A38: B2-T3 | B38: B2 | C38: Sub-task | D38: Mid-edit tab close recovery test | H38: Highest | J38: 2 | K38: QA | L38: M0 Foundation | M38: qa | N38: Done | O38: DraftBackup (local copy + restore only when server copy unchanged), keepalive PATCH on pagehide, beforeunload warning; spec; commit pending | P38: 2026-09-23
A39: B3 | B39: EPIC-B | C39: Story | D39: As an editor, I can build an SOP with structured steps I can reorder and renumber automatically. | E39: Steps are rows as well as content, so they can be cited by ID. | G39: EPIC-B | H39: Highest | I39: 8 | J39: =SUM(J40:J43) | L39: M0 Foundation | M39: p0,m0 | N39: Done | O39: 4/4 sub-tasks done | P39: 2026-09-23
A40: B3-T1 | B40: B3 | C40: Sub-task | D40: document_steps schema and step CRUD API | H40: Highest | J40: 8 | K40: Backend | L40: M0 Foundation | M40: backend | N40: Done | P40: 2026-09-22
...

Sheet Progress
A1: Progress as of 2026-09-23 — derived from the Status column on 'Jira Import'
A3: Epic | B3: Name | C3: Sub-tasks | D3: Done | E3: In Progress | F3: To Do | G3: Blocked | H3: % done | I3: Stories done
A4: A | B4: A — Foundation & tenancy | C4: 20 | D4: 20 | E4: 0 | F4: 0 | G4: 0 | H4: 1 | I4: 5/5
A5: B | B5: B — Editor & document model | C5: 21 | D5: 21 | E5: 0 | F5: 0 | G5: 0 | H5: 1 | I5: 7/7
A6: C | B6: C — Recording capture | C6: 13 | D6: 13 | E6: 0 | F6: 0 | G6: 0 | H6: 1 | I6: 4/4
A7: D | B7: D — AI SOP generation | C7: 22 | D7: 17 | E7: 0 | F7: 0 | G7: 5 | H7: 0.77 | I7: 3/6
A8: E | B8: E — Governance | C8: 18 | D8: 18 | E8: 0 | F8: 0 | G8: 0 | H8: 1 | I8: 6/6
A9: F | B9: F — Permissions | C9: 9 | D9: 9 | E9: 0 | F9: 0 | G9: 0 | H9: 1 | I9: 3/3
A10: G | B10: G — Search & retrieval | C10: 19 | D10: 16 | E10: 0 | F10: 0 | G10: 3 | H10: 0.84 | I10: 3/6
A11: H | B11: H — Chatbot | C11: 16 | D11: 15 | E11: 0 | F11: 0 | G11: 1 | H11: 0.94 | I11: 5/6
A12: I | B12: I — AI utilities | C12: 10 | D12: 10 | E12: 0 | F12: 0 | G12: 0 | H12: 1 | I12: 4/4
A13: J | B13: J — Handbook & acknowledgements | C13: 10 | D13: 10 | E13: 0 | F13: 0 | G13: 0 | H13: 1 | I13: 5/5
A14: K | B14: K — Billing & plans | C14: 11 | D14: 10 | E14: 0 | F14: 0 | G14: 1 | H14: 0.91 | I14: 3/4
A15: L | B15: L — Analytics & operations | C15: 8 | D15: 8 | E15: 0 | F15: 0 | G15: 0 | H15: 1 | I15: 4/4
A16: M | B16: M — Platform & delivery | C16: 17 | D16: 9 | E16: 4 | F16: 4 | G16: 0 | H16: 0.53 | I16: 1/5
A17: Total | C17: 194 | D17: 176 | E17: 4 | F17: 4 | G17: 10 | H17: 0.91
A19: Status meaning
A20: Done | B20: built, lint-clean, unit/feature tests written. As of 2026-09-23 the API passes the raw-query check, Pint, PHPStan level 6 and all 113 PHPUnit tests on SQLite and on MySQL 8.4 locally; the web app passes lint, 35 tests and the production build; CI confirmation pending the push
A21: In Progress | B21: partly built — see the Status note for what is missing
A22: To Do | B22: not started
A23: Blocked | B23: waiting on a decision, keys or material from the team (transcription provider, billing provider, real recordings)
A25: Commits: docs 5029b6e/3bb6c31 · spike 55515b8 · M0 b58a0df · A 11876e5/1c63003 · B 8f9ead3 · skeleton b0f807f · C b92964a · D 34a494e · CI 5e61028 · E 7d65832 · F 754a141 · M3 a7cf59b · docs 39e31cd · I 57d4bd7 · J b107f9e · K 4c59e48 · L 3fb9d6c · B1 44e896b · Pint 5484896 · FR-8xx f826ebd

Sheet Epic Summary
A1: Epic | B1: Name | C1: Stories | D1: Tasks | E1: Story Points | F1: Estimate (h) | G1: Estimate (days) | H1: % of total
A2: A | B2: Foundation & tenancy | C2: 5 | D2: 20 | E2: ='Jira Import'!I2 | F2: ='Jira Import'!J2 | G2: =F2/$C$18 | H2: =IFERROR(F2/$F$15,0)
A3: B | B3: Editor & document model | C3: 7 | D3: 21 | E3: ='Jira Import'!I28 | F3: ='Jira Import'!J28 | G3: =F3/$C$18 | H3: =IFERROR(F3/$F$15,0)
A4: C | B4: Recording capture | C4: 4 | D4: 13 | E4: ='Jira Import'!I57 | F4: ='Jira Import'!J57 | G4: =F4/$C$18 | H4: =IFERROR(F4/$F$15,0)
A5: D | B5: AI SOP generation | C5: 6 | D5: 22 | E5: ='Jira Import'!I75 | F5: ='Jira Import'!J75 | G5: =F5/$C$18 | H5: =IFERROR(F5/$F$15,0)
A6: E | B6: Governance | C6: 6 | D6: 18 | E6: ='Jira Import'!I104 | F6: ='Jira Import'!J104 | G6: =F6/$C$18 | H6: =IFERROR(F6/$F$15,0)
A7: F | B7: Permissions | C7: 3 | D7: 9 | E7: ='Jira Import'!I129 | F7: ='Jira Import'!J129 | G7: =F7/$C$18 | H7: =IFERROR(F7/$F$15,0)
A8: G | B8: Search & retrieval | C8: 6 | D8: 19 | E8: ='Jira Import'!I142 | F8: ='Jira Import'!J142 | G8: =F8/$C$18 | H8: =IFERROR(F8/$F$15,0)
A9: H | B9: Chatbot | C9: 6 | D9: 16 | E9: ='Jira Import'!I168 | F9: ='Jira Import'!J168 | G9: =F9/$C$18 | H9: =IFERROR(F9/$F$15,0)
A10: I | B10: AI utilities | C10: 4 | D10: 10 | E10: ='Jira Import'!I191 | F10: ='Jira Import'!J191 | G10: =F10/$C$18 | H10: =IFERROR(F10/$F$15,0)
A11: J | B11: Handbook & acknowledgements | C11: 5 | D11: 10 | E11: ='Jira Import'!I206 | F11: ='Jira Import'!J206 | G11: =F11/$C$18 | H11: =IFERROR(F11/$F$15,0)
A12: K | B12: Billing & plans | C12: 4 | D12: 11 | E12: ='Jira Import'!I222 | F12: ='Jira Import'!J222 | G12: =F12/$C$18 | H12: =IFERROR(F12/$F$15,0)
A13: L | B13: Analytics & operations | C13: 4 | D13: 8 | E13: ='Jira Import'!I238 | F13: ='Jira Import'!J238 | G13: =F13/$C$18 | H13: =IFERROR(F13/$F$15,0)
A14: M | B14: Platform & delivery | C14: 5 | D14: 17 | E14: ='Jira Import'!I251 | F14: ='Jira Import'!J251 | G14: =F14/$C$18 | H14: =IFERROR(F14/$F$15,0)
B15: Total | C15: =SUM(C2:C14) | D15: =SUM(D2:D14) | E15: =SUM(E2:E14) | F15: =SUM(F2:F14) | G15: =F15/$C$18 | H15: =IFERROR(F15/$F$15,0)
B18: Assumption — hours per working day | C18: 6
B19: Assumption — team capacity, developer-days per week | C19: 10
B20: Estimates are engineering hours only. They exclude discovery, design partner support, recruitment and holiday.

Sheet Milestone Plan
A1: Milestone | B1: Focus | C1: Stories | D1: Story Points | E1: Estimate (h) | F1: Estimate (days) | G1: Elapsed weeks at capacity
A2: M0 Foundation | B2: Auth, tenancy, editor, design system, CI | C2: 16 | D2: =SUMIFS('Jira Import'!I:I,'Jira Import'!L:L,A2,'Jira Import'!C:C,"Story") | E2: =SUMIFS('Jira Import'!J:J,'Jira Import'!L:L,A2,'Jira Import'!C:C,"Story") | F2: =E2/'Epic Summary'!$C$18 | G2: =F2/'Epic Summary'!$C$19
A3: M1 Prove the wedge | B3: Recording capture and AI SOP generation | C3: 11 | D3: =SUMIFS('Jira Import'!I:I,'Jira Import'!L:L,A3,'Jira Import'!C:C,"Story") | E3: =SUMIFS('Jira Import'!J:J,'Jira Import'!L:L,A3,'Jira Import'!C:C,"Story") | F3: =E3/'Epic Summary'!$C$18 | G3: =F3/'Epic Summary'!$C$19
A4: M2 Design partners | B4: Governance and permissions, 5 partners onboarded | C4: 9 | D4: =SUMIFS('Jira Import'!I:I,'Jira Import'!L:L,A4,'Jira Import'!C:C,"Story") | E4: =SUMIFS('Jira Import'!J:J,'Jira Import'!L:L,A4,'Jira Import'!C:C,"Story") | F4: =E4/'Epic Summary'!$C$18 | G4: =F4/'Epic Summary'!$C$19
A5: M3 Retrieval layer | B5: Search, chunking, chatbot with citations | C5: 12 | D5: =SUMIFS('Jira Import'!I:I,'Jira Import'!L:L,A5,'Jira Import'!C:C,"Story") | E5: =SUMIFS('Jira Import'!J:J,'Jira Import'!L:L,A5,'Jira Import'!C:C,"Story") | F5: =E5/'Epic Summary'!$C$18 | G5: =F5/'Epic Summary'!$C$19
A6: M4 Open paid tiers | B6: AI utilities, handbook, billing | C6: 13 | D6: =SUMIFS('Jira Import'!I:I,'Jira Import'!L:L,A6,'Jira Import'!C:C,"Story") | E6: =SUMIFS('Jira Import'!J:J,'Jira Import'!L:L,A6,'Jira Import'!C:C,"Story") | F6: =E6/'Epic Summary'!$C$18 | G6: =F6/'Epic Summary'!$C$19
A7: M5 Scale | B7: Analytics, review cadence, pipeline health | C7: 4 | D7: =SUMIFS('Jira Import'!I:I,'Jira Import'!L:L,A7,'Jira Import'!C:C,"Story") | E7: =SUMIFS('Jira Import'!J:J,'Jira Import'!L:L,A7,'Jira Import'!C:C,"Story") | F7: =E7/'Epic Summary'!$C$18 | G7: =F7/'Epic Summary'!$C$19
B8: Total | C8: =SUM(C2:C7) | D8: =SUM(D2:D7) | E8: =SUM(E2:E7) | F8: =SUM(F2:F7) | G8: =SUM(G2:G7)
B10: Elapsed weeks assumes the capacity on Epic Summary and no parallelism between milestones. M2 and M3 overlap in the roadmap, so real elapsed time is shorter than this total.

Sheet Component Load
A1: Component | B1: Tasks | C1: Estimate (h) | D1: % of build
A2: AI/Pipeline | B2: =COUNTIFS('Jira Import'!K:K,A2) | C2: =SUMIFS('Jira Import'!J:J,'Jira Import'!K:K,A2) | D2: =IFERROR(C2/$C$10,0)
A3: Backend | B3: =COUNTIFS('Jira Import'!K:K,A3) | C3: =SUMIFS('Jira Import'!J:J,'Jira Import'!K:K,A3) | D3: =IFERROR(C3/$C$10,0)
A4: Database | B4: =COUNTIFS('Jira Import'!K:K,A4) | C4: =SUMIFS('Jira Import'!J:J,'Jira Import'!K:K,A4) | D4: =IFERROR(C4/$C$10,0)
A5: Design | B5: =COUNTIFS('Jira Import'!K:K,A5) | C5: =SUMIFS('Jira Import'!J:J,'Jira Import'!K:K,A5) | D5: =IFERROR(C5/$C$10,0)
A6: Frontend | B6: =COUNTIFS('Jira Import'!K:K,A6) | C6: =SUMIFS('Jira Import'!J:J,'Jira Import'!K:K,A6) | D6: =IFERROR(C6/$C$10,0)
A7: Full stack | B7: =COUNTIFS('Jira Import'!K:K,A7) | C7: =SUMIFS('Jira Import'!J:J,'Jira Import'!K:K,A7) | D7: =IFERROR(C7/$C$10,0)
A8: Infra | B8: =COUNTIFS('Jira Import'!K:K,A8) | C8: =SUMIFS('Jira Import'!J:J,'Jira Import'!K:K,A8) | D8: =IFERROR(C8/$C$10,0)
A9: QA | B9: =COUNTIFS('Jira Import'!K:K,A9) | C9: =SUMIFS('Jira Import'!J:J,'Jira Import'!K:K,A9) | D9: =IFERROR(C9/$C$10,0)
A10: Total | B10: =SUM(B2:B9) | C10: =SUM(C2:C9) | D10: =IFERROR(C10/$C$10,0)

Sheet Import Guide
A1: How to import this into Jira
A3: 1 | B3: Save the 'Jira Import' sheet as CSV (File > Save As > CSV, that sheet only).
A4: 2 | B4: In Jira: Settings > System > External System Import > CSV.
A5: 3 | B5: Upload the CSV. On the field-mapping screen, map the columns as below.
A6: 4 | B6: Tick 'Map field value' for Priority if your scheme uses different names.
A7: 5 | B7: Import epics and stories first if your Jira rejects sub-tasks in one pass — filter Issue Type, import in two runs, then re-run with sub-tasks.
A9: Column | B9: Maps to
A10: Issue ID | B10: Issue ID (used only to link parents during import)
A11: Parent ID | B11: Parent ID
A12: Issue Type | B12: Issue Type
A13: Summary | B13: Summary
A14: Description | B14: Description
A15: Epic Name | B15: Epic Name (epics only)
... A22: Labels | B22: Labels
A24: Estimating basis
A25: Story points | B25: Carried from the product backlog document. They size relative complexity and are not converted from hours.
A26: Task hours | B26: Estimated per task, independently of points. Story hours are the sum of their sub-tasks, so points and hours are two separate views and will not correlate perfectly — that is intentional.
A27: Excluded | B27: Discovery, design-partner recruitment and support, project management, holiday, onboarding and rework after user feedback.
A28: Confidence | B28: Epics A, B, C, E, F, J, K and M are conventional work and estimate reliably. Epic D (generation) and Epic G/H (retrieval) contain genuine research risk — treat those hours as a first pass to be revised after the first ten real recordings.
A30: Known correction
A31: Epic B total | B31: The product backlog document listed Epic B as 34 points. The stories in it actually sum to 40, and the backlog total is 367 rather than 361. This workbook uses the corrected figures and the backlog document has been updated to match.
A33: Epic M is new | B33: Design system, CI/CD, environments and observability were not in the original backlog. They are prerequisites rather than overhead, so they are estimated here.
